{"errorMessage": "An error occurred (AccessDeniedException) when calling the Invoke operation: User: arn:aws:sts::023718874208:assumed-role/crypto-alert-app-dev-us-east-1-lambdaRole/crypto-alert-app-dev-fetcher is not authorized to perform: lambda:InvokeFunction on resource: arn:aws:lambda:us-east-1:023718874208:function:crypto-alert-app-dev-analyzer because no identity-based policy allows the lambda:InvokeFunction action", "errorType": "ClientError", "requestId": "897eecc4-a483-4351-ad0f-f979c2845449", "stackTrace": ["  File \"/var/task/services/fetcher/handler.py\", line 60, in handler\n    lambda_client.invoke(\n", "  File \"/var/task/services/fetcher/botocore/client.py\", line 595, in _api_call\n    return self._make_api_call(operation_name, kwargs)\n", "  File \"/var/task/services/fetcher/botocore/context.py\", line 123, in wrapper\n    return func(*args, **kwargs)\n", "  File \"/var/task/services/fetcher/botocore/client.py\", line 1058, in _make_api_call\n    raise error_class(parsed_response, operation_name)\n"]}